2024-03-09 15:27:20,242 INFO    StreamThr :11040 [internal.py:wandb_internal():86] W&B internal server running at pid: 11040, started at: 2024-03-09 15:27:20.241555
2024-03-09 15:27:20,243 DEBUG   HandlerThread:11040 [handler.py:handle_request():146] handle_request: status
2024-03-09 15:27:20,268 INFO    WriterThread:11040 [datastore.py:open_for_write():87] open: C:\Users\the_r\Projects\deep-rl-msa\wandb\run-20240309_152720-z9v19eug\run-z9v19eug.wandb
2024-03-09 15:27:20,269 DEBUG   SenderThread:11040 [sender.py:send():378] send: header
2024-03-09 15:27:20,462 DEBUG   SenderThread:11040 [sender.py:send():378] send: run
2024-03-09 15:27:20,838 ERROR   SenderThread:11040 [internal_api.py:execute():373] 403 response executing GraphQL.
2024-03-09 15:27:20,838 ERROR   SenderThread:11040 [internal_api.py:execute():374] {"errors":[{"message":"permission denied","path":["upsertBucket"],"extensions":{"code":"PERMISSION_ERROR"}}],"data":{"upsertBucket":null}}
2024-03-09 15:27:20,844 ERROR   SenderThread:11040 [sender.py:send_run():950] It appears that you do not have permission to access the requested resource. Please reach out to the project owner to grant you access. If you have the correct permissions, verify that there are no issues with your networking setup.(Error 403: Forbidden)
Traceback (most recent call last):
  File "C:\Users\the_r\anaconda3\lib\site-packages\wandb\sdk\lib\retry.py", line 131, in __call__
    result = self._call_fn(*args, **kwargs)
  File "C:\Users\the_r\anaconda3\lib\site-packages\wandb\sdk\internal\internal_api.py", line 369, in execute
    return self.client.execute(*args, **kwargs)  # type: ignore
  File "C:\Users\the_r\anaconda3\lib\site-packages\wandb\vendor\gql-0.2.0\wandb_gql\client.py", line 52, in execute
    result = self._get_result(document, *args, **kwargs)
  File "C:\Users\the_r\anaconda3\lib\site-packages\wandb\vendor\gql-0.2.0\wandb_gql\client.py", line 60, in _get_result
    return self.transport.execute(document, *args, **kwargs)
  File "C:\Users\the_r\anaconda3\lib\site-packages\wandb\sdk\lib\gql_request.py", line 59, in execute
    request.raise_for_status()
  File "C:\Users\the_r\anaconda3\lib\site-packages\requests\models.py", line 1021, in raise_for_status
    raise HTTPError(http_error_msg, response=self)
requests.exceptions.HTTPError: 403 Client Error: Forbidden for url: https://api.wandb.ai/graphql

During handling of the above exception, another exception occurred:

Traceback (most recent call last):
  File "C:\Users\the_r\anaconda3\lib\site-packages\wandb\sdk\internal\sender.py", line 948, in send_run
    self._init_run(run, config_value_dict)
  File "C:\Users\the_r\anaconda3\lib\site-packages\wandb\sdk\internal\sender.py", line 990, in _init_run
    server_run, inserted, server_messages = self._api.upsert_run(
  File "C:\Users\the_r\anaconda3\lib\site-packages\wandb\apis\normalize.py", line 73, in wrapper
    raise err
  File "C:\Users\the_r\anaconda3\lib\site-packages\wandb\apis\normalize.py", line 41, in wrapper
    return func(*args, **kwargs)
  File "C:\Users\the_r\anaconda3\lib\site-packages\wandb\sdk\internal\internal_api.py", line 2216, in upsert_run
    response = self.gql(
  File "C:\Users\the_r\anaconda3\lib\site-packages\wandb\sdk\internal\internal_api.py", line 341, in gql
    ret = self._retry_gql(
  File "C:\Users\the_r\anaconda3\lib\site-packages\wandb\sdk\lib\retry.py", line 147, in __call__
    retry_timedelta_triggered = check_retry_fn(e)
  File "C:\Users\the_r\anaconda3\lib\site-packages\wandb\util.py", line 968, in check_retry_fn
    return fallback_retry_fn(e)
  File "C:\Users\the_r\anaconda3\lib\site-packages\wandb\util.py", line 910, in no_retry_auth
    raise CommError(
wandb.errors.CommError: It appears that you do not have permission to access the requested resource. Please reach out to the project owner to grant you access. If you have the correct permissions, verify that there are no issues with your networking setup.(Error 403: Forbidden)
2024-03-09 15:27:25,867 DEBUG   HandlerThread:11040 [handler.py:handle_request():146] handle_request: status_report
2024-03-09 15:27:30,905 DEBUG   HandlerThread:11040 [handler.py:handle_request():146] handle_request: status_report
2024-03-09 15:27:35,927 DEBUG   HandlerThread:11040 [handler.py:handle_request():146] handle_request: status_report
2024-03-09 15:27:40,962 DEBUG   HandlerThread:11040 [handler.py:handle_request():146] handle_request: status_report
2024-03-09 15:27:46,001 DEBUG   HandlerThread:11040 [handler.py:handle_request():146] handle_request: status_report
2024-03-09 15:27:51,044 DEBUG   HandlerThread:11040 [handler.py:handle_request():146] handle_request: status_report
2024-03-09 15:27:56,075 DEBUG   HandlerThread:11040 [handler.py:handle_request():146] handle_request: status_report
2024-03-09 15:28:01,112 DEBUG   HandlerThread:11040 [handler.py:handle_request():146] handle_request: status_report
2024-03-09 15:28:06,131 DEBUG   HandlerThread:11040 [handler.py:handle_request():146] handle_request: status_report
2024-03-09 15:28:11,173 DEBUG   HandlerThread:11040 [handler.py:handle_request():146] handle_request: status_report
2024-03-09 15:28:16,210 DEBUG   HandlerThread:11040 [handler.py:handle_request():146] handle_request: status_report
2024-03-09 15:28:21,244 DEBUG   HandlerThread:11040 [handler.py:handle_request():146] handle_request: status_report
2024-03-09 15:28:26,271 DEBUG   HandlerThread:11040 [handler.py:handle_request():146] handle_request: status_report
2024-03-09 15:28:31,309 DEBUG   HandlerThread:11040 [handler.py:handle_request():146] handle_request: status_report
2024-03-09 15:28:36,336 DEBUG   HandlerThread:11040 [handler.py:handle_request():146] handle_request: status_report
2024-03-09 15:28:41,363 DEBUG   HandlerThread:11040 [handler.py:handle_request():146] handle_request: status_report
2024-03-09 15:28:46,381 DEBUG   HandlerThread:11040 [handler.py:handle_request():146] handle_request: status_report
2024-03-09 15:28:51,409 DEBUG   HandlerThread:11040 [handler.py:handle_request():146] handle_request: status_report
2024-03-09 15:28:56,442 DEBUG   HandlerThread:11040 [handler.py:handle_request():146] handle_request: status_report
2024-03-09 15:29:01,466 DEBUG   HandlerThread:11040 [handler.py:handle_request():146] handle_request: status_report
2024-03-09 15:29:06,493 DEBUG   HandlerThread:11040 [handler.py:handle_request():146] handle_request: status_report
2024-03-09 15:29:11,519 DEBUG   HandlerThread:11040 [handler.py:handle_request():146] handle_request: status_report
2024-03-09 15:29:16,548 DEBUG   HandlerThread:11040 [handler.py:handle_request():146] handle_request: status_report
2024-03-09 15:29:21,573 DEBUG   HandlerThread:11040 [handler.py:handle_request():146] handle_request: status_report
2024-03-09 15:29:26,602 DEBUG   HandlerThread:11040 [handler.py:handle_request():146] handle_request: status_report
2024-03-09 15:29:31,627 DEBUG   HandlerThread:11040 [handler.py:handle_request():146] handle_request: status_report
2024-03-09 15:29:36,662 DEBUG   HandlerThread:11040 [handler.py:handle_request():146] handle_request: status_report
2024-03-09 15:29:41,710 DEBUG   HandlerThread:11040 [handler.py:handle_request():146] handle_request: status_report
2024-03-09 15:29:46,747 DEBUG   HandlerThread:11040 [handler.py:handle_request():146] handle_request: status_report
2024-03-09 15:29:51,790 DEBUG   HandlerThread:11040 [handler.py:handle_request():146] handle_request: status_report
2024-03-09 15:29:56,812 DEBUG   HandlerThread:11040 [handler.py:handle_request():146] handle_request: status_report
